2020-10-15 10:25:28,256 ERROR: Exception on /favicon.ico [GET] [in c:\users\heikki\appdata\local\programs\python\python38\lib\site-packages\flask\app.py:1891]
Traceback (most recent call last):
  File "c:\users\heikki\appdata\local\programs\python\python38\lib\site-packages\flask\app.py", line 1950, in full_dispatch_request
    rv = self.dispatch_request()
  File "c:\users\heikki\appdata\local\programs\python\python38\lib\site-packages\flask\app.py", line 1926, in dispatch_request
    self.raise_routing_exception(req)
  File "c:\users\heikki\appdata\local\programs\python\python38\lib\site-packages\flask\app.py", line 1908, in raise_routing_exception
    raise request.routing_exception
  File "c:\users\heikki\appdata\local\programs\python\python38\lib\site-packages\flask\ctx.py", line 350, in match_request
    result = self.url_adapter.match(return_rule=True)
  File "c:\users\heikki\appdata\local\programs\python\python38\lib\site-packages\werkzeug\routing.py", line 1945, in match
    raise NotFound()
werkzeug.exceptions.NotFound: 404 Not Found: The requested URL was not found on the server. If you entered the URL manually please check your spelling and try again.

During handling of the above exception, another exception occurred:

Traceback (most recent call last):
  File "c:\users\heikki\appdata\local\programs\python\python38\lib\site-packages\flask\app.py", line 2447, in wsgi_app
    response = self.full_dispatch_request()
  File "c:\users\heikki\appdata\local\programs\python\python38\lib\site-packages\flask\app.py", line 1952, in full_dispatch_request
    rv = self.handle_user_exception(e)
  File "c:\users\heikki\appdata\local\programs\python\python38\lib\site-packages\flask\app.py", line 1816, in handle_user_exception
    return self.handle_http_exception(e)
  File "c:\users\heikki\appdata\local\programs\python\python38\lib\site-packages\flask\app.py", line 1744, in handle_http_exception
    return handler(e)
  File "C:\Users\Heikki\Documents\WebDev\colegios\Flask\soleed\errors.py", line 8, in not_found_error
    return render_template('404.html'), 404
  File "c:\users\heikki\appdata\local\programs\python\python38\lib\site-packages\flask\templating.py", line 137, in render_template
    return _render(
  File "c:\users\heikki\appdata\local\programs\python\python38\lib\site-packages\flask\templating.py", line 120, in _render
    rv = template.render(context)
  File "c:\users\heikki\appdata\local\programs\python\python38\lib\site-packages\jinja2\environment.py", line 1090, in render
    self.environment.handle_exception()
  File "c:\users\heikki\appdata\local\programs\python\python38\lib\site-packages\jinja2\environment.py", line 832, in handle_exception
    reraise(*rewrite_traceback_stack(source=source))
  File "c:\users\heikki\appdata\local\programs\python\python38\lib\site-packages\jinja2\_compat.py", line 28, in reraise
    raise value.with_traceback(tb)
  File "C:\Users\Heikki\Documents\WebDev\colegios\Flask\soleed\templates\404.html", line 1, in top-level template code
    {% extends "base.html" %}
  File "C:\Users\Heikki\Documents\WebDev\colegios\Flask\soleed\templates\base.html", line 18, in top-level template code
    {% block header %}
  File "C:\Users\Heikki\Documents\WebDev\colegios\Flask\soleed\templates\404.html", line 8, in block "header"
    {{ super() }}
  File "C:\Users\Heikki\Documents\WebDev\colegios\Flask\soleed\templates\base.html", line 23, in block "header"
    {{ nav_link('index', 'Home') }}
  File "c:\users\heikki\appdata\local\programs\python\python38\lib\site-packages\jinja2\runtime.py", line 679, in _invoke
    rv = self._func(*arguments)
  File "C:\Users\Heikki\Documents\WebDev\colegios\Flask\soleed\templates\macros.html", line 2, in template
    {% if request.endpoint.endswith(endpoint) %}
jinja2.exceptions.UndefinedError: 'None' has no attribute 'endswith'
2020-10-15 10:27:18,146 ERROR: Exception on /favicon.ico [GET] [in c:\users\heikki\appdata\local\programs\python\python38\lib\site-packages\flask\app.py:1891]
Traceback (most recent call last):
  File "c:\users\heikki\appdata\local\programs\python\python38\lib\site-packages\flask\app.py", line 1950, in full_dispatch_request
    rv = self.dispatch_request()
  File "c:\users\heikki\appdata\local\programs\python\python38\lib\site-packages\flask\app.py", line 1926, in dispatch_request
    self.raise_routing_exception(req)
  File "c:\users\heikki\appdata\local\programs\python\python38\lib\site-packages\flask\app.py", line 1908, in raise_routing_exception
    raise request.routing_exception
  File "c:\users\heikki\appdata\local\programs\python\python38\lib\site-packages\flask\ctx.py", line 350, in match_request
    result = self.url_adapter.match(return_rule=True)
  File "c:\users\heikki\appdata\local\programs\python\python38\lib\site-packages\werkzeug\routing.py", line 1945, in match
    raise NotFound()
werkzeug.exceptions.NotFound: 404 Not Found: The requested URL was not found on the server. If you entered the URL manually please check your spelling and try again.

During handling of the above exception, another exception occurred:

Traceback (most recent call last):
  File "c:\users\heikki\appdata\local\programs\python\python38\lib\site-packages\flask\app.py", line 2447, in wsgi_app
    response = self.full_dispatch_request()
  File "c:\users\heikki\appdata\local\programs\python\python38\lib\site-packages\flask\app.py", line 1952, in full_dispatch_request
    rv = self.handle_user_exception(e)
  File "c:\users\heikki\appdata\local\programs\python\python38\lib\site-packages\flask\app.py", line 1816, in handle_user_exception
    return self.handle_http_exception(e)
  File "c:\users\heikki\appdata\local\programs\python\python38\lib\site-packages\flask\app.py", line 1744, in handle_http_exception
    return handler(e)
  File "C:\Users\Heikki\Documents\WebDev\colegios\Flask\soleed\errors.py", line 8, in not_found_error
    return render_template('404.html'), 404
  File "c:\users\heikki\appdata\local\programs\python\python38\lib\site-packages\flask\templating.py", line 137, in render_template
    return _render(
  File "c:\users\heikki\appdata\local\programs\python\python38\lib\site-packages\flask\templating.py", line 120, in _render
    rv = template.render(context)
  File "c:\users\heikki\appdata\local\programs\python\python38\lib\site-packages\jinja2\environment.py", line 1090, in render
    self.environment.handle_exception()
  File "c:\users\heikki\appdata\local\programs\python\python38\lib\site-packages\jinja2\environment.py", line 832, in handle_exception
    reraise(*rewrite_traceback_stack(source=source))
  File "c:\users\heikki\appdata\local\programs\python\python38\lib\site-packages\jinja2\_compat.py", line 28, in reraise
    raise value.with_traceback(tb)
  File "C:\Users\Heikki\Documents\WebDev\colegios\Flask\soleed\templates\404.html", line 1, in top-level template code
    {% extends "base.html" %}
  File "C:\Users\Heikki\Documents\WebDev\colegios\Flask\soleed\templates\base.html", line 18, in top-level template code
    {% block header %}
  File "C:\Users\Heikki\Documents\WebDev\colegios\Flask\soleed\templates\404.html", line 8, in block "header"
    {{ super() }}
  File "C:\Users\Heikki\Documents\WebDev\colegios\Flask\soleed\templates\base.html", line 23, in block "header"
    {{ nav_link('index', 'Home') }}
  File "c:\users\heikki\appdata\local\programs\python\python38\lib\site-packages\jinja2\runtime.py", line 679, in _invoke
    rv = self._func(*arguments)
  File "C:\Users\Heikki\Documents\WebDev\colegios\Flask\soleed\templates\macros.html", line 2, in template
    {% if request.endpoint.endswith(endpoint) %}
jinja2.exceptions.UndefinedError: 'None' has no attribute 'endswith'
